<sdf version='1.11'>
  <model name='dragon'>
    <static>true</static>
    <link name='base_link'>
      <gravity>false</gravity>
      <inertial>
        <pose>0.094083375991619769 0.31392124549819073 0.02355789200391184 0 0 0</pose>
        <mass>3.2123976475049201</mass>
        <inertia>
          <ixx>0.28615501559474132</ixx>
          <ixy>-0.076412822410160119</ixy>
          <ixz>0.0014552482556793301</ixz>
          <iyy>0.29996932674844812</iyy>
          <iyz>-0.001932335490017784</iyz>
          <izz>0.58140284867119696</izz>
        </inertia>
      </inertial>
      <collision name='base_link_collision'>
        <pose>0 0 0 0 0 0</pose>
        <geometry>
          <mesh>
            <scale>1 1 1</scale>
            <uri>model://serial-articulated/meshes/base_link.STL</uri>
          </mesh>
        </geometry>
      </collision>
      <collision name='base_link_fixed_joint_lump__joint1_pitch_collision_1'>
        <pose>0.41105000000000003 0.751 -0.042411999999999998 0 0.0012441000000000002 3.1415853071795872</pose>
        <geometry>
          <mesh>
            <scale>1 1 1</scale>
            <uri>model://serial-articulated/meshes/joint1_pitch.STL</uri>
          </mesh>
        </geometry>
      </collision>
      <collision name='base_link_fixed_joint_lump__joint1_yaw_collision_2'>
        <pose>0.45349657127694659 0.67999968816815959 0.0001408413459373786 1.570844099999992 -4.5698332895582894e-09 -1.570800000002843</pose>
        <geometry>
          <mesh>
            <scale>1 1 1</scale>
            <uri>model://serial-articulated/meshes/joint1_yaw.STL</uri>
          </mesh>
        </geometry>
      </collision>
      <collision name='base_link_fixed_joint_lump__Joint2_pitch_collision_3'>
        <pose>0.41104910643746267 -1.561125325677537e-07 -0.042414183327252913 -3.141541207179595 -4.569833366160561e-09 -1.5708000000028433</pose>
        <geometry>
          <mesh>
            <scale>1 1 1</scale>
            <uri>model://serial-articulated/meshes/Joint2_pitch.STL</uri>
          </mesh>
        </geometry>
      </collision>
      <collision name='base_link_fixed_joint_lump__joint2_yaw_collision_4'>
        <pose>0.33999376847548579 -0.042499894917988217 -5.8386109438382516e-06 1.570792657970653 5.1446410214871967e-05 3.1415853071769742</pose>
        <geometry>
          <mesh>
            <scale>1 1 1</scale>
            <uri>model://serial-articulated/meshes/joint2_yaw.STL</uri>
          </mesh>
        </geometry>
      </collision>
      <collision name='base_link_fixed_joint_lump__joint3_pitch_collision_5'>
        <pose>-0.34000373191817418 5.2565502569601463e-06 -0.042540666188315653 7.3420293452184246e-06 -4.4100000008085954e-05 -7.3463858662453209e-06</pose>
        <geometry>
          <mesh>
            <scale>1 1 1</scale>
            <uri>model://serial-articulated/meshes/joint3_pitch.STL</uri>
          </mesh>
        </geometry>
      </collision>
      <collision name='base_link_fixed_joint_lump__joint3_yaw_collision_6'>
        <pose>-0.38250508455758409 0.071005256745348522 -4.2019196704767843e-05 1.5707558999730218 -7.3418673495855403e-06 1.570792653937914</pose>
        <geometry>
          <mesh>
            <scale>1 1 1</scale>
            <uri>model://serial-articulated/meshes/joint3_yaw.STL</uri>
          </mesh>
        </geometry>
      </collision>
      <collision name='base_link_fixed_joint_lump__link4_arm_roll_collision_7'>
        <pose>-0.44000565494703281 0.41100513756288598 0.044958152457951851 -1.570724063884311 -0.97708531051172465 -1.5708598965289029</pose>
        <geometry>
          <mesh>
            <scale>1 1 1</scale>
            <uri>model://serial-articulated/meshes/link4_arm_roll.STL</uri>
          </mesh>
        </geometry>
      </collision>
      <collision name='base_link_fixed_joint_lump__link3_arm_roll_collision_8'>
        <pose>-7.4993181363725006e-06 0.1000024377774794 0.044977192357190332 -1.5707933537916741 -0.57554855358541879 3.1415876877894982</pose>
        <geometry>
          <mesh>
            <scale>1 1 1</scale>
            <uri>model://serial-articulated/meshes/link3_arm_roll.STL</uri>
          </mesh>
        </geometry>
      </collision>
      <collision name='base_link_fixed_joint_lump__link2_arm_roll_collision_9'>
        <pose>0.52060298715257469 -0.34000055835008391 -0.003260047929155345 2.2087640015835199 0.87206879575160012 -1.0545058706842991</pose>
        <geometry>
          <mesh>
            <scale>1 1 1</scale>
            <uri>model://serial-articulated/meshes/link2_arm_roll.STL</uri>
          </mesh>
        </geometry>
      </collision>
      <collision name='base_link_fixed_joint_lump__link1_arm_roll_collision_10'>
        <pose>0.751 -0.65100000000000002 0.044999999999999998 -1.5707999999999995 -0.97713000000000028 -3.1415853071795872</pose>
        <geometry>
          <mesh>
            <scale>1 1 1</scale>
            <uri>model://serial-articulated/meshes/link1_arm_roll.STL</uri>
          </mesh>
        </geometry>
      </collision>
      <visual name='base_link_visual'>
        <pose>0 0 0 0 0 0</pose>
        <geometry>
          <mesh>
            <scale>1 1 1</scale>
            <uri>model://serial-articulated/meshes/base_link.STL</uri>
          </mesh>
        </geometry>
        <material>
          <diffuse>1 1 1 1</diffuse>
          <ambient>1 1 1 1</ambient>
        </material>
      </visual>
      <visual name='base_link_fixed_joint_lump__joint1_pitch_visual_1'>
        <pose>0.41105000000000003 0.751 -0.042411999999999998 0 0.0012441000000000002 3.1415853071795872</pose>
        <geometry>
          <mesh>
            <scale>1 1 1</scale>
            <uri>model://serial-articulated/meshes/joint1_pitch.STL</uri>
          </mesh>
        </geometry>
        <material>
          <diffuse>0.808823526 0.774509847 0.735294163 1</diffuse>
          <ambient>0.808823526 0.774509847 0.735294163 1</ambient>
        </material>
      </visual>
      <visual name='base_link_fixed_joint_lump__joint1_yaw_visual_2'>
        <pose>0.45349657127694659 0.67999968816815959 0.0001408413459373786 1.570844099999992 -4.5698332895582894e-09 -1.570800000002843</pose>
        <geometry>
          <mesh>
            <scale>1 1 1</scale>
            <uri>model://serial-articulated/meshes/joint1_yaw.STL</uri>
          </mesh>
        </geometry>
        <material>
          <diffuse>1 1 1 1</diffuse>
          <ambient>1 1 1 1</ambient>
        </material>
      </visual>
      <visual name='base_link_fixed_joint_lump__Joint2_pitch_visual_3'>
        <pose>0.41104910643746267 -1.561125325677537e-07 -0.042414183327252913 -3.141541207179595 -4.569833366160561e-09 -1.5708000000028433</pose>
        <geometry>
          <mesh>
            <scale>1 1 1</scale>
            <uri>model://serial-articulated/meshes/Joint2_pitch.STL</uri>
          </mesh>
        </geometry>
        <material>
          <diffuse>0.808823526 0.774509847 0.735294163 1</diffuse>
          <ambient>0.808823526 0.774509847 0.735294163 1</ambient>
        </material>
      </visual>
      <visual name='base_link_fixed_joint_lump__joint2_yaw_visual_4'>
        <pose>0.33999376847548579 -0.042499894917988217 -5.8386109438382516e-06 1.570792657970653 5.1446410214871967e-05 3.1415853071769742</pose>
        <geometry>
          <mesh>
            <scale>1 1 1</scale>
            <uri>model://serial-articulated/meshes/joint2_yaw.STL</uri>
          </mesh>
        </geometry>
        <material>
          <diffuse>1 1 1 1</diffuse>
          <ambient>1 1 1 1</ambient>
        </material>
      </visual>
      <visual name='base_link_fixed_joint_lump__joint3_pitch_visual_5'>
        <pose>-0.34000373191817418 5.2565502569601463e-06 -0.042540666188315653 7.3420293452184246e-06 -4.4100000008085954e-05 -7.3463858662453209e-06</pose>
        <geometry>
          <mesh>
            <scale>1 1 1</scale>
            <uri>model://serial-articulated/meshes/joint3_pitch.STL</uri>
          </mesh>
        </geometry>
        <material>
          <diffuse>0.808823526 0.774509847 0.735294163 1</diffuse>
          <ambient>0.808823526 0.774509847 0.735294163 1</ambient>
        </material>
      </visual>
      <visual name='base_link_fixed_joint_lump__joint3_yaw_visual_6'>
        <pose>-0.38250508455758409 0.071005256745348522 -4.2019196704767843e-05 1.5707558999730218 -7.3418673495855403e-06 1.570792653937914</pose>
        <geometry>
          <mesh>
            <scale>1 1 1</scale>
            <uri>model://serial-articulated/meshes/joint3_yaw.STL</uri>
          </mesh>
        </geometry>
        <material>
          <diffuse>1 1 1 1</diffuse>
          <ambient>1 1 1 1</ambient>
        </material>
      </visual>
      <visual name='base_link_fixed_joint_lump__link4_arm_roll_visual_7'>
        <pose>-0.44000565494703281 0.41100513756288598 0.044958152457951851 -1.570724063884311 -0.97708531051172465 -1.5708598965289029</pose>
        <geometry>
          <mesh>
            <scale>1 1 1</scale>
            <uri>model://serial-articulated/meshes/link4_arm_roll.STL</uri>
          </mesh>
        </geometry>
        <material>
          <diffuse>0.990196109 1 1 1</diffuse>
          <ambient>0.990196109 1 1 1</ambient>
        </material>
      </visual>
      <visual name='base_link_fixed_joint_lump__link3_arm_roll_visual_8'>
        <pose>-7.4993181363725006e-06 0.1000024377774794 0.044977192357190332 -1.5707933537916741 -0.57554855358541879 3.1415876877894982</pose>
        <geometry>
          <mesh>
            <scale>1 1 1</scale>
            <uri>model://serial-articulated/meshes/link3_arm_roll.STL</uri>
          </mesh>
        </geometry>
        <material>
          <diffuse>0.990196109 1 1 1</diffuse>
          <ambient>0.990196109 1 1 1</ambient>
        </material>
      </visual>
      <visual name='base_link_fixed_joint_lump__link2_arm_roll_visual_9'>
        <pose>0.52060298715257469 -0.34000055835008391 -0.003260047929155345 2.2087640015835199 0.87206879575160012 -1.0545058706842991</pose>
        <geometry>
          <mesh>
            <scale>1 1 1</scale>
            <uri>model://serial-articulated/meshes/link2_arm_roll.STL</uri>
          </mesh>
        </geometry>
        <material>
          <diffuse>0.990196109 1 1 1</diffuse>
          <ambient>0.990196109 1 1 1</ambient>
        </material>
      </visual>
      <visual name='base_link_fixed_joint_lump__link1_arm_roll_visual_10'>
        <pose>0.751 -0.65100000000000002 0.044999999999999998 -1.5707999999999995 -0.97713000000000028 -3.1415853071795872</pose>
        <geometry>
          <mesh>
            <scale>1 1 1</scale>
            <uri>model://serial-articulated/meshes/link1_arm_roll.STL</uri>
          </mesh>
        </geometry>
        <material>
          <diffuse>0.990196109 1 1 1</diffuse>
          <ambient>0.990196109 1 1 1</ambient>
        </material>
      </visual>
    </link>
    <joint name='link4_left_prop' type='revolute'>
      <pose relative_to='base_link'>-0.51330839277215479 0.41921974724216832 0.1134260191923436 0.020518361402719645 -3.7382211264238785e-05 -1.6182129218475649e-06</pose>
      <parent>base_link</parent>
      <child>link4_left_spin</child>
      <axis>
        <xyz>-0.16991000000000001 -0.020216999999999999 -0.98524999999999996</xyz>
        <limit>
          <lower>-inf</lower>
          <upper>inf</upper>
        </limit>
        <dynamics>
          <spring_reference>0</spring_reference>
          <spring_stiffness>0</spring_stiffness>
        </dynamics>
      </axis>
    </joint>
    <link name='link4_left_spin'>
      <gravity>false</gravity>
      <pose relative_to='link4_left_prop'>0 0 0 0 0 0</pose>
      <inertial>
        <pose>5.0936339579532596e-07 -2.54296163793022e-07 0.0043082663718138998 0 0 0</pose>
        <mass>0.0119145296235532</mass>
        <inertia>
          <ixx>4.7986214125918196e-06</ixx>
          <ixy>8.2875678609994599e-06</ixy>
          <ixz>-3.01248004075787e-12</ixz>
          <iyy>1.6077422263507501e-05</iyy>
          <iyz>3.6697308298421497e-12</iyz>
          <izz>2.05873107453045e-05</izz>
        </inertia>
      </inertial>
      <collision name='link4_left_spin_collision'>
        <pose>0 0 0 0 0 0</pose>
        <geometry>
          <mesh>
            <scale>1 1 1</scale>
            <uri>model://serial-articulated/meshes/link4_left_spin.STL</uri>
          </mesh>
        </geometry>
      </collision>
      <visual name='link4_left_spin_visual'>
        <pose>0 0 0 0 0 0</pose>
        <geometry>
          <mesh>
            <scale>1 1 1</scale>
            <uri>model://serial-articulated/meshes/link4_left_spin.STL</uri>
          </mesh>
        </geometry>
        <material>
          <diffuse>0.990196109 1 1 1</diffuse>
          <ambient>0.990196109 1 1 1</ambient>
        </material>
      </visual>
    </link>
    <joint name='link4_right_prop' type='revolute'>
      <pose relative_to='base_link'>-0.1667084152247883 0.41703619126012342 0.1137900761089965 2.0064889848413379 4.3471432481843853e-05 3.141586925495131</pose>
      <parent>base_link</parent>
      <child>link4_right_spin</child>
      <axis>
        <xyz>0 0 1</xyz>
        <limit>
          <lower>-inf</lower>
          <upper>inf</upper>
        </limit>
        <dynamics>
          <spring_reference>0</spring_reference>
          <spring_stiffness>0</spring_stiffness>
        </dynamics>
      </axis>
    </joint>
    <link name='link4_right_spin'>
      <gravity>false</gravity>
      <pose relative_to='link4_right_prop'>0 0 0 0 0 0</pose>
      <inertial>
        <pose>-5.1206361684208403e-07 2.5467935299561299e-07 0.0043082716485359097 0 0 0</pose>
        <mass>0.0119145517108038</mass>
        <inertia>
          <ixx>4.7924512653397898e-06</ixx>
          <ixy>8.2834104069104198e-06</ixy>
          <ixz>2.9489363863815699e-12</ixz>
          <iyy>1.6083761369675499e-05</iyy>
          <iyz>-3.6326338387179999e-12</iyz>
          <izz>2.0587479692032001e-05</izz>
        </inertia>
      </inertial>
      <collision name='link4_right_spin_collision'>
        <pose>0 0 0 0 0 0</pose>
        <geometry>
          <mesh>
            <scale>1 1 1</scale>
            <uri>model://serial-articulated/meshes/link4_right_spin.STL</uri>
          </mesh>
        </geometry>
      </collision>
      <visual name='link4_right_spin_visual'>
        <pose>0 0 0 0 0 0</pose>
        <geometry>
          <mesh>
            <scale>1 1 1</scale>
            <uri>model://serial-articulated/meshes/link4_right_spin.STL</uri>
          </mesh>
        </geometry>
        <material>
          <diffuse>0.990196109 1 1 1</diffuse>
          <ambient>0.990196109 1 1 1</ambient>
        </material>
      </visual>
    </link>
    <joint name='link3_left_prop' type='revolute'>
      <pose relative_to='base_link'>0.0049719485355487758 -0.1732974074060156 0.1137365291395516 1.2187522267817741 4.4933414887911241e-06 1.570789897756357</pose>
      <parent>base_link</parent>
      <child>link3_left_spin</child>
      <axis>
        <xyz>0 0 1</xyz>
        <limit>
          <lower>-inf</lower>
          <upper>inf</upper>
        </limit>
        <dynamics>
          <spring_reference>0</spring_reference>
          <spring_stiffness>0</spring_stiffness>
        </dynamics>
      </axis>
    </joint>
    <link name='link3_left_spin'>
      <gravity>false</gravity>
      <pose relative_to='link3_left_prop'>0 0 0 0 0 0</pose>
      <inertial>
        <pose>2.73046578846969e-07 5.7386769990522301e-07 0.0043082117476412598 0 0 0</pose>
        <mass>0.0119147088004385</mass>
        <inertia>
          <ixx>1.6263983374953499e-05</ixx>
          <ixy>-8.1584660418568499e-06</ixy>
          <ixz>-2.9217991626821201e-12</ixz>
          <iyy>4.6130560183606898e-06</iyy>
          <iyz>1.7470016448315399e-14</iyz>
          <izz>2.05883046094045e-05</izz>
        </inertia>
      </inertial>
      <collision name='link3_left_spin_collision'>
        <pose>0 0 0 0 0 0</pose>
        <geometry>
          <mesh>
            <scale>1 1 1</scale>
            <uri>model://serial-articulated/meshes/link3_left_spin.STL</uri>
          </mesh>
        </geometry>
      </collision>
      <visual name='link3_left_spin_visual'>
        <pose>0 0 0 0 0 0</pose>
        <geometry>
          <mesh>
            <scale>1 1 1</scale>
            <uri>model://serial-articulated/meshes/link3_left_spin.STL</uri>
          </mesh>
        </geometry>
        <material>
          <diffuse>0.990196109 1 1 1</diffuse>
          <ambient>0.990196109 1 1 1</ambient>
        </material>
      </visual>
    </link>
    <joint name='link3_right_prop' type='revolute'>
      <pose relative_to='base_link'>-0.0020576579648598492 0.17330261295149799 0.1124623350330531 0.17075511961306233 -4.9472677211839035e-07 -1.5707965929750671</pose>
      <parent>base_link</parent>
      <child>link3_right_spin</child>
      <axis>
        <xyz>0 0 1</xyz>
        <limit>
          <lower>-inf</lower>
          <upper>inf</upper>
        </limit>
        <dynamics>
          <spring_reference>0</spring_reference>
          <spring_stiffness>0</spring_stiffness>
        </dynamics>
      </axis>
    </joint>
    <link name='link3_right_spin'>
      <gravity>false</gravity>
      <pose relative_to='link3_right_prop'>0 0 0 0 0 0</pose>
      <inertial>
        <pose>-2.5617679511036302e-07 -5.6628507827741204e-07 0.0043082696237262503 0 0 0</pose>
        <mass>0.011914607071025299</mass>
        <inertia>
          <ixx>1.6501820132457999e-05</ixx>
          <ixy>-7.9825401941668902e-06</ixy>
          <ixz>3.5403624003570002e-12</ixz>
          <iyy>4.3744678562245803e-06</iyy>
          <iyz>5.6472291988431999e-13</iyz>
          <izz>2.0587553991969399e-05</izz>
        </inertia>
      </inertial>
      <collision name='link3_right_spin_collision'>
        <pose>0 0 0 0 0 0</pose>
        <geometry>
          <mesh>
            <scale>1 1 1</scale>
            <uri>model://serial-articulated/meshes/link3_right_spin.STL</uri>
          </mesh>
        </geometry>
      </collision>
      <visual name='link3_right_spin_visual'>
        <pose>0 0 0 0 0 0</pose>
        <geometry>
          <mesh>
            <scale>1 1 1</scale>
            <uri>model://serial-articulated/meshes/link3_right_spin.STL</uri>
          </mesh>
        </geometry>
        <material>
          <diffuse>0.990196109 1 1 1</diffuse>
          <ambient>0.990196109 1 1 1</ambient>
        </material>
      </visual>
    </link>
    <joint name='link2_left_prop' type='revolute'>
      <pose relative_to='base_link'>0.23834250895801509 0.34316174007101441 0.11378723595809059 2.9543414902628502 0.0057539083742912311 -5.6043909901602051e-06</pose>
      <parent>base_link</parent>
      <child>link2_left_spin</child>
      <axis>
        <xyz>0 0 1</xyz>
        <limit>
          <lower>-inf</lower>
          <upper>inf</upper>
        </limit>
        <dynamics>
          <spring_reference>0</spring_reference>
          <spring_stiffness>0</spring_stiffness>
        </dynamics>
      </axis>
    </joint>
    <link name='link2_left_spin'>
      <gravity>false</gravity>
      <pose relative_to='link2_left_prop'>0 0 0 0 0 0</pose>
      <inertial>
        <pose>1.75439487964946e-07 -5.4595662946077497e-07 0.0043082238273990398 0 0 0</pose>
        <mass>0.0119146770370482</mass>
        <inertia>
          <ixx>1.7897955188503798e-05</ixx>
          <ixy>6.6961122712129901e-06</ixy>
          <ixz>-2.9382143107992398e-13</ixz>
          <iyy>2.9782851323175499e-06</iyy>
          <iyz>7.1775198346959003e-12</iyz>
          <izz>2.0587501473632701e-05</izz>
        </inertia>
      </inertial>
      <collision name='link2_left_spin_collision'>
        <pose>0 0 0 0 0 0</pose>
        <geometry>
          <mesh>
            <scale>1 1 1</scale>
            <uri>model://serial-articulated/meshes/link2_left_spin.STL</uri>
          </mesh>
        </geometry>
      </collision>
      <visual name='link2_left_spin_visual'>
        <pose>0 0 0 0 0 0</pose>
        <geometry>
          <mesh>
            <scale>1 1 1</scale>
            <uri>model://serial-articulated/meshes/link2_left_spin.STL</uri>
          </mesh>
        </geometry>
        <material>
          <diffuse>0.990196109 1 1 1</diffuse>
          <ambient>0.990196109 1 1 1</ambient>
        </material>
      </visual>
    </link>
    <joint name='link2_right_prop' type='revolute'>
      <pose relative_to='base_link'>0.58494518876901802 0.32389280942058479 0.11227225760167719 3.0470002275566439 7.9405578916000359e-05 -3.080791835178275</pose>
      <parent>base_link</parent>
      <child>link2_right_spin</child>
      <axis>
        <xyz>0 0 1</xyz>
        <limit>
          <lower>-inf</lower>
          <upper>inf</upper>
        </limit>
        <dynamics>
          <spring_reference>0</spring_reference>
          <spring_stiffness>0</spring_stiffness>
        </dynamics>
      </axis>
    </joint>
    <link name='link2_right_spin'>
      <gravity>false</gravity>
      <pose relative_to='link2_right_prop'>0 0 0 0 0 0</pose>
      <inertial>
        <pose>-5.5534239007393204e-07 1.5379311291141599e-07 0.0043082113420697104 0 0 0</pose>
        <mass>0.0119145275478498</mass>
        <inertia>
          <ixx>2.4788926237237398e-06</ixx>
          <ixy>6.09419636431981e-06</ixy>
          <ixz>-2.6916859631944099e-13</ixz>
          <iyy>1.83970876472519e-05</iyy>
          <iyz>-9.8340209359989906e-13</iyz>
          <izz>2.0587245953127e-05</izz>
        </inertia>
      </inertial>
      <collision name='link2_right_spin_collision'>
        <pose>0 0 0 0 0 0</pose>
        <geometry>
          <mesh>
            <scale>1 1 1</scale>
            <uri>model://serial-articulated/meshes/link2_right_spin.STL</uri>
          </mesh>
        </geometry>
      </collision>
      <visual name='link2_right_spin_visual'>
        <pose>0 0 0 0 0 0</pose>
        <geometry>
          <mesh>
            <scale>1 1 1</scale>
            <uri>model://serial-articulated/meshes/link2_right_spin.STL</uri>
          </mesh>
        </geometry>
        <material>
          <diffuse>0.990196109 1 1 1</diffuse>
          <ambient>0.990196109 1 1 1</ambient>
        </material>
      </visual>
    </link>
    <joint name='link1_left_prop' type='revolute'>
      <pose relative_to='base_link'>0.054490834877236487 0.58599686395884754 0.11307280261578601 3.100134070008949 -3.1719221314626014e-05 1.5473043204294201</pose>
      <parent>base_link</parent>
      <child>link1_left_spin</child>
      <axis>
        <xyz>0 0.049088 -0.99878999999999996</xyz>
        <limit>
          <lower>-inf</lower>
          <upper>inf</upper>
        </limit>
        <dynamics>
          <spring_reference>0</spring_reference>
          <spring_stiffness>0</spring_stiffness>
        </dynamics>
      </axis>
    </joint>
    <link name='link1_left_spin'>
      <gravity>false</gravity>
      <pose relative_to='link1_left_prop'>0 0 0 0 0 0</pose>
      <inertial>
        <pose>-6.6576237556237295e-07 7.51971221471526e-08 0.0043082201008794296 0 0 0</pose>
        <mass>0.011914561956256399</mass>
        <inertia>
          <ixx>8.9256336721573604e-07</ixx>
          <ixy>3.06123858172512e-06</ixy>
          <ixz>5.6671762227492601e-12</ixz>
          <iyy>1.99835060436476e-05</iyy>
          <iyz>1.6706195567005999e-12</iyz>
          <izz>2.0587338830599999e-05</izz>
        </inertia>
      </inertial>
      <collision name='link1_left_spin_collision'>
        <pose>0 0 0 0 0 0</pose>
        <geometry>
          <mesh>
            <scale>1 1 1</scale>
            <uri>model://serial-articulated/meshes/link1_left_spin.STL</uri>
          </mesh>
        </geometry>
      </collision>
      <visual name='link1_left_spin_visual'>
        <pose>0 0 0 0 0 0</pose>
        <geometry>
          <mesh>
            <scale>1 1 1</scale>
            <uri>model://serial-articulated/meshes/link1_left_spin.STL</uri>
          </mesh>
        </geometry>
        <material>
          <diffuse>0.990196109 1 1 1</diffuse>
          <ambient>0.990196109 1 1 1</ambient>
        </material>
      </visual>
    </link>
    <joint name='link1_right_prop' type='revolute'>
      <pose relative_to='base_link'>0.066010589885560411 0.93249691248709943 0.113574215087704 3.1338385870735519 3.1421936024115987e-05 -1.5942883335337443</pose>
      <parent>base_link</parent>
      <child>link1_right_spin</child>
      <axis>
        <xyz>-0.18626999999999999 0.0062962000000000001 -0.98248000000000002</xyz>
        <limit>
          <lower>-inf</lower>
          <upper>inf</upper>
        </limit>
        <dynamics>
          <spring_reference>0</spring_reference>
          <spring_stiffness>0</spring_stiffness>
        </dynamics>
      </axis>
    </joint>
    <link name='link1_right_spin'>
      <gravity>false</gravity>
      <pose relative_to='link1_right_prop'>0 0 0 0 0 0</pose>
      <inertial>
        <pose>6.9315839235084595e-07 6.2994502919577795e-08 0.00430821663494839 0 0 0</pose>
        <mass>0.0119145513741783</mass>
        <inertia>
          <ixx>4.7611968447637199e-07</ixx>
          <ixy>-1.11645184011423e-06</ixy>
          <ixz>-5.1518207968535502e-12</ixz>
          <iyy>2.0399736262995001e-05</iyy>
          <iyz>-2.9852301022851101e-12</iyz>
          <izz>2.05871235175461e-05</izz>
        </inertia>
      </inertial>
      <collision name='link1_right_spin_collision'>
        <pose>0 0 0 0 0 0</pose>
        <geometry>
          <mesh>
            <scale>1 1 1</scale>
            <uri>model://serial-articulated/meshes/link1_right_spin.STL</uri>
          </mesh>
        </geometry>
      </collision>
      <visual name='link1_right_spin_visual'>
        <pose>0 0 0 0 0 0</pose>
        <geometry>
          <mesh>
            <scale>1 1 1</scale>
            <uri>model://serial-articulated/meshes/link1_right_spin.STL</uri>
          </mesh>
        </geometry>
        <material>
          <diffuse>0.990196109 1 1 1</diffuse>
          <ambient>0.990196109 1 1 1</ambient>
        </material>
      </visual>
    </link>
    <frame name='link4_cross_arm' attached_to='joint3_yaw'>
      <pose>0.34000000000000002 0.044999999999999998 -0.057500000000000002 0 0 2.1644999999999999</pose>
    </frame>
    <frame name='link4_arm_roll' attached_to='link4_cross_arm'>
      <pose>0 0 0 0 0 0</pose>
    </frame>
    <frame name='link4_main_tube' attached_to='joint3_pitch'>
      <pose>-0.042500000000000003 0.070999999999999994 0.042500000000000003 1.5708 -5.5511151231257827e-17 1.5708</pose>
    </frame>
    <frame name='joint3_yaw' attached_to='link4_main_tube'>
      <pose>0 0 0 0 0 0</pose>
    </frame>
    <frame name='Joint3_dummy' attached_to='joint2_yaw'>
      <pose>0.68000000000000005 -0.042500000000000003 0.042500000000000003 1.5708 -4.2351647362715017e-22 -3.1415853071795872</pose>
    </frame>
    <frame name='joint3_pitch' attached_to='Joint3_dummy'>
      <pose>0 0 0 0 0 0</pose>
    </frame>
    <frame name='link3_cross_arm' attached_to='joint2_yaw'>
      <pose>0.34000000000000002 0.044999999999999998 0.14249999999999999 -3.1415853071795872 -8.4703294725430034e-22 0.57560000000000033</pose>
    </frame>
    <frame name='link3_arm_roll' attached_to='link3_cross_arm'>
      <pose>0 0 0 0 0 0</pose>
    </frame>
    <frame name='link3_main_tube' attached_to='Joint2_pitch'>
      <pose>0.042500000000000003 0.071053000000000005 -0.042411999999999998 -1.5708 5.5511151231257827e-17 1.5708</pose>
    </frame>
    <frame name='joint2_yaw' attached_to='link3_main_tube'>
      <pose>0 0 0 0 0 0</pose>
    </frame>
    <frame name='joint2_dummy' attached_to='joint1_yaw'>
      <pose>0.68000000000000005 -0.042553000000000001 0.042446999999999999 1.5708 0 0</pose>
    </frame>
    <frame name='Joint2_pitch' attached_to='joint2_dummy'>
      <pose>0 0 0 0 0 0</pose>
    </frame>
    <frame name='link2_cross_arm' attached_to='joint1_yaw'>
      <pose>1.02 -0.0034041000000000002 -0.067110000000000003 0.22793999999999984 0.32310000000000022 -0.93982999999999994</pose>
    </frame>
    <frame name='link2_arm_roll' attached_to='link2_cross_arm'>
      <pose>0 0 0 0 0 0</pose>
    </frame>
    <frame name='link2_main_tube' attached_to='joint1_pitch'>
      <pose>-0.042500000000000003 0.070999999999999994 0.042500000000000003 1.5696000000000001 -5.5511151231257827e-17 1.5708</pose>
    </frame>
    <frame name='joint1_yaw' attached_to='link2_main_tube'>
      <pose>0 0 0 0 0 0</pose>
    </frame>
    <frame name='joint1_dummy' attached_to='base_link'>
      <pose>0.41105000000000003 0.751 -0.042411999999999998 0 0.0012441000000000002 3.1415853071795872</pose>
    </frame>
    <frame name='joint1_pitch' attached_to='joint1_dummy'>
      <pose>0 0 0 0 0 0</pose>
    </frame>
    <frame name='link1_cross_arm' attached_to='base_link'>
      <pose>0.751 -0.65100000000000002 0.044999999999999998 -1.5707999999999993 -0.97713000000000028 -3.1415853071795872</pose>
    </frame>
    <frame name='link1_arm_roll' attached_to='link1_cross_arm'>
      <pose>0 0 0 0 0 0</pose>
    </frame>


  </model>
</sdf>
